414
1
sample_test/runtime_error.py